Workbook
Name Slicer_Category: #N/A
Name Slicer_PaymentMethod: #N/A
Name Slicer_Region: #N/A

Sheet CustomerMaster
A1: CustomerID | B1: CustomerName | C1: City
A2: CUST1035 | B2: Customer_0 | C2: Bangalore
A3: CUST1292 | B3: Customer_1 | C3: Hyderabad
A4: CUST1164 | B4: Customer_2 | C4: Mumbai
A5: CUST1170 | B5: Customer_3 | C5: Hyderabad
A6: CUST1203 | B6: Customer_4 | C6: Hyderabad
A7: CUST1143 | B7: Customer_5 | C7: Mumbai
A8: CUST1263 | B8: Customer_6 | C8: Delhi
A9: CUST1188 | B9: Customer_7 | C9: Delhi
A10: CUST1147 | B10: Customer_8 | C10: Bangalore
A11: CUST1300 | B11: Customer_9 | C11: Mumbai
A12: CUST1276 | B12: Customer_10 | C12: Delhi
... A287: CUST1079 | B287: Customer_285 | C287: Bangalore

Sheet ProductMaster
A1: ProductID | B1: ProductName | C1: Category
A2: PROD150 | B2: Product_0 | C2: Home
A3: PROD111 | B3: Product_1 | C3: Fashion
A4: PROD149 | B4: Product_2 | C4: Home
A5: PROD104 | B5: Product_3 | C5: Electronics
A6: PROD132 | B6: Product_4 | C6: Home
A7: PROD108 | B7: Product_5 | C7: Fashion
A8: PROD102 | B8: Product_6 | C8: Beauty
A9: PROD131 | B9: Product_7 | C9: Grocery
A10: PROD120 | B10: Product_8 | C10: Grocery
A11: PROD113 | B11: Product_9 | C11: Beauty
A12: PROD112 | B12: Product_10 | C12: Grocery
... A51: PROD126 | B51: Product_49 | C51: Fashion

Sheet RegionMaster
A1: Region | B1: Manager
A2: North | B2: A
A3: South | B3: B
A4: East | B4: C
A5: West | B5: D

Sheet FlipkartSales
A1: OrderID | B1: CustomerID | C1: ProductID | D1: OrderDate | E1: DeliveryDate | F1: CancelDate | G1: Region | H1: Category | I1: PaymentMethod | J1: DeliveryStatus | K1: SalesAmount | L1: Order Month | M1: Delivery_Months | N1: Delivery Category | O1: Delivery Days | P1: Order Flag | Q1: Order performance | R1: Customer Name | S1: Product Name | T1: Region Manager
A2: ORD10000 | B2: CUST1276 | C2: PROD124 | D2: 45767 | E2: 45769 | G2: West | H2: Beauty | I2: Credit Card | J2: Delivered | K2: 1997.79 | L2: =TEXT(D2,"MMMM") -> April | M2: =IF(NOT(ISBLANK(E2)),TEXT(E2,"MMMM"),"Cancelled") -> April | N2: =IF(F2="","Delivered","Cancelled") -> Delivered | O2: =IF(E2="","Order Cancelled",_xlfn.DAYS(E2,D2)) -> 2 | P2: =IF(F2="","Completed","Cancelled") -> Completed | Q2: =IF(O2="Order Cancelled","Cancelled",IF(O2<=2,"Fast","Slow")) -> Fast | R2: =_xlfn.XLOOKUP(B2,CustomerMaster!$A$2:$A$287,CustomerMaster!$B$2:$B$287) -> Customer_10 | S2: =_xlfn.XLOOKUP(C2,ProductMaster!$A$2:$A$51,ProductMaster!$B$2:$B$51) -> Product_13 | T2: =_xlfn.XLOOKUP(G2,RegionMaster!$A$2:$A$5,RegionMaster!$B$2:$B$5) -> D
A3: ORD10001 | B3: CUST1297 | C3: PROD147 | D3: 45766 | F3: 45768 | G3: North | H3: Grocery | I3: Debit Card | J3: Returned | K3: 4763.43 | L3: =TEXT(D3,"MMMM") -> April | M3: =IF(NOT(ISBLANK(E3)),TEXT(E3,"MMMM"),"Cancelled") -> Cancelled | N3: =IF(F3="","Delivered","Cancelled") -> Cancelled | O3: =IF(E3="","Order Cancelled",_xlfn.DAYS(E3,D3)) -> Order Cancelled | P3: =IF(F3="","Completed","Cancelled") -> Cancelled | Q3: =IF(O3="Order Cancelled","Cancelled",IF(O3<=2,"Fast","Slow")) -> Cancelled | R3: =_xlfn.XLOOKUP(B3,CustomerMaster!$A$2:$A$287,CustomerMaster!$B$2:$B$287) -> Customer_140 | S3: =_xlfn.XLOOKUP(C3,ProductMaster!$A$2:$A$51,ProductMaster!$B$2:$B$51) -> Product_27 | T3: =_xlfn.XLOOKUP(G3,RegionMaster!$A$2:$A$5,RegionMaster!$B$2:$B$5) -> A
A4: ORD10002 | B4: CUST1030 | C4: PROD109 | D4: 45691 | E4: 45694 | G4: North | H4: Home | I4: COD | J4: Returned | K4: 3713.57 | L4: =TEXT(D4,"MMMM") -> February | M4: =IF(NOT(ISBLANK(E4)),TEXT(E4,"MMMM"),"Cancelled") -> February | N4: =IF(F4="","Delivered","Cancelled") -> Delivered | O4: =IF(E4="","Order Cancelled",_xlfn.DAYS(E4,D4)) -> 3 | P4: =IF(F4="","Completed","Cancelled") -> Completed | Q4: =IF(O4="Order Cancelled","Cancelled",IF(O4<=2,"Fast","Slow")) -> Slow | R4: =_xlfn.XLOOKUP(B4,CustomerMaster!$A$2:$A$287,CustomerMaster!$B$2:$B$287) -> Customer_136 | S4: =_xlfn.XLOOKUP(C4,ProductMaster!$A$2:$A$51,ProductMaster!$B$2:$B$51) -> Product_20 | T4: =_xlfn.XLOOKUP(G4,RegionMaster!$A$2:$A$5,RegionMaster!$B$2:$B$5) -> A
A5: ORD10003 | B5: CUST1237 | C5: PROD113 | D5: 45682 | E5: 45686 | G5: South | H5: Fashion | I5: Credit Card | J5: Cancelled | K5: 3073.56 | L5: =TEXT(D5,"MMMM") -> January | M5: =IF(NOT(ISBLANK(E5)),TEXT(E5,"MMMM"),"Cancelled") -> January | N5: =IF(F5="","Delivered","Cancelled") -> Delivered | O5: =IF(E5="","Order Cancelled",_xlfn.DAYS(E5,D5)) -> 4 | P5: =IF(F5="","Completed","Cancelled") -> Completed | Q5: =IF(O5="Order Cancelled","Cancelled",IF(O5<=2,"Fast","Slow")) -> Slow | R5: =_xlfn.XLOOKUP(B5,CustomerMaster!$A$2:$A$287,CustomerMaster!$B$2:$B$287) -> Customer_86 | S5: =_xlfn.XLOOKUP(C5,ProductMaster!$A$2:$A$51,ProductMaster!$B$2:$B$51) -> Product_9 | T5: =_xlfn.XLOOKUP(G5,RegionMaster!$A$2:$A$5,RegionMaster!$B$2:$B$5) -> B
A6: ORD10004 | B6: CUST1003 | C6: PROD129 | D6: 45736 | F6: 45738 | G6: North | H6: Home | I6: Credit Card | J6: Delivered | K6: 948.89 | L6: =TEXT(D6,"MMMM") -> March | M6: =IF(NOT(ISBLANK(E6)),TEXT(E6,"MMMM"),"Cancelled") -> Cancelled | N6: =IF(F6="","Delivered","Cancelled") -> Cancelled | O6: =IF(E6="","Order Cancelled",_xlfn.DAYS(E6,D6)) -> Order Cancelled | P6: =IF(F6="","Completed","Cancelled") -> Cancelled | Q6: =IF(O6="Order Cancelled","Cancelled",IF(O6<=2,"Fast","Slow")) -> Cancelled | R6: =_xlfn.XLOOKUP(B6,CustomerMaster!$A$2:$A$287,CustomerMaster!$B$2:$B$287) -> Customer_232 | S6: =_xlfn.XLOOKUP(C6,ProductMaster!$A$2:$A$51,ProductMaster!$B$2:$B$51) -> Product_42 | T6: =_xlfn.XLOOKUP(G6,RegionMaster!$A$2:$A$5,RegionMaster!$B$2:$B$5) -> A
A7: ORD10005 | B7: CUST1193 | C7: PROD118 | D7: 45660 | E7: 45662 | G7: South | H7: Grocery | I7: Credit Card | J7: Delivered | K7: 948.77 | L7: =TEXT(D7,"MMMM") -> January | M7: =IF(NOT(ISBLANK(E7)),TEXT(E7,"MMMM"),"Cancelled") -> January | N7: =IF(F7="","Delivered","Cancelled") -> Delivered | O7: =IF(E7="","Order Cancelled",_xlfn.DAYS(E7,D7)) -> 2 | P7: =IF(F7="","Completed","Cancelled") -> Completed | Q7: =IF(O7="Order Cancelled","Cancelled",IF(O7<=2,"Fast","Slow")) -> Fast | R7: =_xlfn.XLOOKUP(B7,CustomerMaster!$A$2:$A$287,CustomerMaster!$B$2:$B$287) -> Customer_265 | S7: =_xlfn.XLOOKUP(C7,ProductMaster!$A$2:$A$51,ProductMaster!$B$2:$B$51) -> Product_21 | T7: =_xlfn.XLOOKUP(G7,RegionMaster!$A$2:$A$5,RegionMaster!$B$2:$B$5) -> B
A8: ORD10006 | B8: CUST1033 | C8: PROD122 | D8: 45695 | E8: 45700 | G8: North | H8: Beauty | I8: Net Banking | J8: Returned | K8: 478.8 | L8: =TEXT(D8,"MMMM") -> February | M8: =IF(NOT(ISBLANK(E8)),TEXT(E8,"MMMM"),"Cancelled") -> February | N8: =IF(F8="","Delivered","Cancelled") -> Delivered | O8: =IF(E8="","Order Cancelled",_xlfn.DAYS(E8,D8)) -> 5 | P8: =IF(F8="","Completed","Cancelled") -> Completed | Q8: =IF(O8="Order Cancelled","Cancelled",IF(O8<=2,"Fast","Slow")) -> Slow | R8: =_xlfn.XLOOKUP(B8,CustomerMaster!$A$2:$A$287,CustomerMaster!$B$2:$B$287) -> Customer_250 | S8: =_xlfn.XLOOKUP(C8,ProductMaster!$A$2:$A$51,ProductMaster!$B$2:$B$51) -> Product_39 | T8: =_xlfn.XLOOKUP(G8,RegionMaster!$A$2:$A$5,RegionMaster!$B$2:$B$5) -> A
A9: ORD10007 | B9: CUST1293 | C9: PROD112 | D9: 45665 | E9: 45670 | G9: West | H9: Grocery | I9: UPI | J9: Cancelled | K9: 4357.65 | L9: =TEXT(D9,"MMMM") -> January | M9: =IF(NOT(ISBLANK(E9)),TEXT(E9,"MMMM"),"Cancelled") -> January | N9: =IF(F9="","Delivered","Cancelled") -> Delivered | O9: =IF(E9="","Order Cancelled",_xlfn.DAYS(E9,D9)) -> 5 | P9: =IF(F9="","Completed","Cancelled") -> Completed | Q9: =IF(O9="Order Cancelled","Cancelled",IF(O9<=2,"Fast","Slow")) -> Slow | R9: =_xlfn.XLOOKUP(B9,CustomerMaster!$A$2:$A$287,CustomerMaster!$B$2:$B$287) -> Customer_60 | S9: =_xlfn.XLOOKUP(C9,ProductMaster!$A$2:$A$51,ProductMaster!$B$2:$B$51) -> Product_10 | T9: =_xlfn.XLOOKUP(G9,RegionMaster!$A$2:$A$5,RegionMaster!$B$2:$B$5) -> D
A10: ORD10008 | B10: CUST1228 | C10: PROD107 | D10: 45718 | E10: 45721 | G10: North | H10: Electronics | I10: Debit Card | J10: Cancelled | K10: 3085.35 | L10: =TEXT(D10,"MMMM") -> March | M10: =IF(NOT(ISBLANK(E10)),TEXT(E10,"MMMM"),"Cancelled") -> March | N10: =IF(F10="","Delivered","Cancelled") -> Delivered | O10: =IF(E10="","Order Cancelled",_xlfn.DAYS(E10,D10)) -> 3 | P10: =IF(F10="","Completed","Cancelled") -> Completed | Q10: =IF(O10="Order Cancelled","Cancelled",IF(O10<=2,"Fast","Slow")) -> Slow | R10: =_xlfn.XLOOKUP(B10,CustomerMaster!$A$2:$A$287,CustomerMaster!$B$2:$B$287) -> Customer_91 | S10: =_xlfn.XLOOKUP(C10,ProductMaster!$A$2:$A$51,ProductMaster!$B$2:$B$51) -> Product_43 | T10: =_xlfn.XLOOKUP(G10,RegionMaster!$A$2:$A$5,RegionMaster!$B$2:$B$5) -> A
A11: ORD10009 | B11: CUST1159 | C11: PROD120 | D11: 45688 | E11: 45693 | G11: East | H11: Electronics | I11: Net Banking | J11: Delivered | K11: 3598.75 | L11: =TEXT(D11,"MMMM") -> January | M11: =IF(NOT(ISBLANK(E11)),TEXT(E11,"MMMM"),"Cancelled") -> February | N11: =IF(F11="","Delivered","Cancelled") -> Delivered | O11: =IF(E11="","Order Cancelled",_xlfn.DAYS(E11,D11)) -> 5 | P11: =IF(F11="","Completed","Cancelled") -> Completed | Q11: =IF(O11="Order Cancelled","Cancelled",IF(O11<=2,"Fast","Slow")) -> Slow | R11: =_xlfn.XLOOKUP(B11,CustomerMaster!$A$2:$A$287,CustomerMaster!$B$2:$B$287) -> Customer_26 | S11: =_xlfn.XLOOKUP(C11,ProductMaster!$A$2:$A$51,ProductMaster!$B$2:$B$51) -> Product_8 | T11: =_xlfn.XLOOKUP(G11,RegionMaster!$A$2:$A$5,RegionMaster!$B$2:$B$5) -> C
A12: ORD10010 | B12: CUST1227 | C12: PROD139 | D12: 45682 | E12: 45684 | G12: South | H12: Grocery | I12: Credit Card | J12: Delivered | K12: 298.81 | L12: =TEXT(D12,"MMMM") -> January | M12: =IF(NOT(ISBLANK(E12)),TEXT(E12,"MMMM"),"Cancelled") -> January | N12: =IF(F12="","Delivered","Cancelled") -> Delivered | O12: =IF(E12="","Order Cancelled",_xlfn.DAYS(E12,D12)) -> 2 | P12: =IF(F12="","Completed","Cancelled") -> Completed | Q12: =IF(O12="Order Cancelled","Cancelled",IF(O12<=2,"Fast","Slow")) -> Fast | R12: =_xlfn.XLOOKUP(B12,CustomerMaster!$A$2:$A$287,CustomerMaster!$B$2:$B$287) -> Customer_68 | S12: =_xlfn.XLOOKUP(C12,ProductMaster!$A$2:$A$51,ProductMaster!$B$2:$B$51) -> Product_15 | T12: =_xlfn.XLOOKUP(G12,RegionMaster!$A$2:$A$5,RegionMaster!$B$2:$B$5) -> B
A13: ORD10011 | B13: CUST1132 | C13: PROD110 | D13: 45761 | E13: 45765 | G13: East | H13: Home | I13: Credit Card | J13: Returned | K13: 4855.57 | L13: =TEXT(D13,"MMMM") -> April | M13: =IF(NOT(ISBLANK(E13)),TEXT(E13,"MMMM"),"Cancelled") -> April | N13: =IF(F13="","Delivered","Cancelled") -> Delivered | O13: =IF(E13="","Order Cancelled",_xlfn.DAYS(E13,D13)) -> 4 | P13: =IF(F13="","Completed","Cancelled") -> Completed | Q13: =IF(O13="Order Cancelled","Cancelled",IF(O13<=2,"Fast","Slow")) -> Slow | R13: =_xlfn.XLOOKUP(B13,CustomerMaster!$A$2:$A$287,CustomerMaster!$B$2:$B$287) -> Customer_44 | S13: =_xlfn.XLOOKUP(C13,ProductMaster!$A$2:$A$51,ProductMaster!$B$2:$B$51) -> Product_19 | T13: =_xlfn.XLOOKUP(G13,RegionMaster!$A$2:$A$5,RegionMaster!$B$2:$B$5) -> C
A14: ORD10012 | B14: CUST1105 | C14: PROD115 | D14: 45728 | F14: 45730 | G14: South | H14: Beauty | I14: Credit Card | J14: Returned | K14: 4195.72 | L14: =TEXT(D14,"MMMM") -> March | M14: =IF(NOT(ISBLANK(E14)),TEXT(E14,"MMMM"),"Cancelled") -> Cancelled | N14: =IF(F14="","Delivered","Cancelled") -> Cancelled | O14: =IF(E14="","Order Cancelled",_xlfn.DAYS(E14,D14)) -> Order Cancelled | P14: =IF(F14="","Completed","Cancelled") -> Cancelled | Q14: =IF(O14="Order Cancelled","Cancelled",IF(O14<=2,"Fast","Slow")) -> Cancelled | R14: =_xlfn.XLOOKUP(B14,CustomerMaster!$A$2:$A$287,CustomerMaster!$B$2:$B$287) -> Customer_11 | S14: =_xlfn.XLOOKUP(C14,ProductMaster!$A$2:$A$51,ProductMaster!$B$2:$B$51) -> Product_40 | T14: =_xlfn.XLOOKUP(G14,RegionMaster!$A$2:$A$5,RegionMaster!$B$2:$B$5) -> B
A15: ORD10013 | B15: CUST1165 | C15: PROD141 | D15: 45769 | E15: 45771 | G15: West | H15: Electronics | I15: UPI | J15: Cancelled | K15: 1219.23 | L15: =TEXT(D15,"MMMM") -> April | M15: =IF(NOT(ISBLANK(E15)),TEXT(E15,"MMMM"),"Cancelled") -> April | N15: =IF(F15="","Delivered","Cancelled") -> Delivered | O15: =IF(E15="","Order Cancelled",_xlfn.DAYS(E15,D15)) -> 2 | P15: =IF(F15="","Completed","Cancelled") -> Completed | Q15: =IF(O15="Order Cancelled","Cancelled",IF(O15<=2,"Fast","Slow")) -> Fast | R15: =_xlfn.XLOOKUP(B15,CustomerMaster!$A$2:$A$287,CustomerMaster!$B$2:$B$287) -> Customer_155 | S15: =_xlfn.XLOOKUP(C15,ProductMaster!$A$2:$A$51,ProductMaster!$B$2:$B$51) -> Product_29 | T15: =_xlfn.XLOOKUP(G15,RegionMaster!$A$2:$A$5,RegionMaster!$B$2:$B$5) -> D
A16: ORD10014 | B16: CUST1017 | C16: PROD108 | D16: 45750 | F16: 45752 | G16: South | H16: Electronics | I16: COD | J16: Delivered | K16: 1072.76 | L16: =TEXT(D16,"MMMM") -> April | M16: =IF(NOT(ISBLANK(E16)),TEXT(E16,"MMMM"),"Cancelled") -> Cancelled | N16: =IF(F16="","Delivered","Cancelled") -> Cancelled | O16: =IF(E16="","Order Cancelled",_xlfn.DAYS(E16,D16)) -> Order Cancelled | P16: =IF(F16="","Completed","Cancelled") -> Cancelled | Q16: =IF(O16="Order Cancelled","Cancelled",IF(O16<=2,"Fast","Slow")) -> Cancelled | R16: =_xlfn.XLOOKUP(B16,CustomerMaster!$A$2:$A$287,CustomerMaster!$B$2:$B$287) -> Customer_61 | S16: =_xlfn.XLOOKUP(C16,ProductMaster!$A$2:$A$51,ProductMaster!$B$2:$B$51) -> Product_5 | T16: =_xlfn.XLOOKUP(G16,RegionMaster!$A$2:$A$5,RegionMaster!$B$2:$B$5) -> B
A17: ORD10015 | B17: CUST1006 | C17: PROD128 | D17: 45690 | F17: 45690 | G17: East | H17: Grocery | I17: UPI | J17: Returned | K17: 1080.34 | L17: =TEXT(D17,"MMMM") -> February | M17: =IF(NOT(ISBLANK(E17)),TEXT(E17,"MMMM"),"Cancelled") -> Cancelled | N17: =IF(F17="","Delivered","Cancelled") -> Cancelled | O17: =IF(E17="","Order Cancelled",_xlfn.DAYS(E17,D17)) -> Order Cancelled | P17: =IF(F17="","Completed","Cancelled") -> Cancelled | Q17: =IF(O17="Order Cancelled","Cancelled",IF(O17<=2,"Fast","Slow")) -> Cancelled | R17: =_xlfn.XLOOKUP(B17,CustomerMaster!$A$2:$A$287,CustomerMaster!$B$2:$B$287) -> Customer_218 | S17: =_xlfn.XLOOKUP(C17,ProductMaster!$A$2:$A$51,ProductMaster!$B$2:$B$51) -> Product_44 | T17: =_xlfn.XLOOKUP(G17,RegionMaster!$A$2:$A$5,RegionMaster!$B$2:$B$5) -> C
A18: ORD10016 | B18: CUST1128 | C18: PROD102 | D18: 45683 | E18: 45684 | G18: West | H18: Grocery | I18: UPI | J18: Delivered | K18: 1660.36 | L18: =TEXT(D18,"MMMM") -> January | M18: =IF(NOT(ISBLANK(E18)),TEXT(E18,"MMMM"),"Cancelled") -> January | N18: =IF(F18="","Delivered","Cancelled") -> Delivered | O18: =IF(E18="","Order Cancelled",_xlfn.DAYS(E18,D18)) -> 1 | P18: =IF(F18="","Completed","Cancelled") -> Completed | Q18: =IF(O18="Order Cancelled","Cancelled",IF(O18<=2,"Fast","Slow")) -> Fast | R18: =_xlfn.XLOOKUP(B18,CustomerMaster!$A$2:$A$287,CustomerMaster!$B$2:$B$287) -> Customer_255 | S18: =_xlfn.XLOOKUP(C18,ProductMaster!$A$2:$A$51,ProductMaster!$B$2:$B$51) -> Product_6 | T18: =_xlfn.XLOOKUP(G18,RegionMaster!$A$2:$A$5,RegionMaster!$B$2:$B$5) -> D
A19: ORD10017 | B19: CUST1241 | C19: PROD102 | D19: 45770 | E19: 45775 | G19: South | H19: Fashion | I19: COD | J19: Returned | K19: 2718.83 | L19: =TEXT(D19,"MMMM") -> April | M19: =IF(NOT(ISBLANK(E19)),TEXT(E19,"MMMM"),"Cancelled") -> April | N19: =IF(F19="","Delivered","Cancelled") -> Delivered | O19: =IF(E19="","Order Cancelled",_xlfn.DAYS(E19,D19)) -> 5 | P19: =IF(F19="","Completed","Cancelled") -> Completed | Q19: =IF(O19="Order Cancelled","Cancelled",IF(O19<=2,"Fast","Slow")) -> Slow | R19: =_xlfn.XLOOKUP(B19,CustomerMaster!$A$2:$A$287,CustomerMaster!$B$2:$B$287) -> Customer_205 | S19: =_xlfn.XLOOKUP(C19,ProductMaster!$A$2:$A$51,ProductMaster!$B$2:$B$51) -> Product_6 | T19: =_xlfn.XLOOKUP(G19,RegionMaster!$A$2:$A$5,RegionMaster!$B$2:$B$5) -> B
A20: ORD10018 | B20: CUST1108 | C20: PROD139 | D20: 45659 | E20: 45661 | G20: North | H20: Grocery | I20: UPI | J20: Returned | K20: 2273.34 | L20: =TEXT(D20,"MMMM") -> January | M20: =IF(NOT(ISBLANK(E20)),TEXT(E20,"MMMM"),"Cancelled") -> January | N20: =IF(F20="","Delivered","Cancelled") -> Delivered | O20: =IF(E20="","Order Cancelled",_xlfn.DAYS(E20,D20)) -> 2 | P20: =IF(F20="","Completed","Cancelled") -> Completed | Q20: =IF(O20="Order Cancelled","Cancelled",IF(O20<=2,"Fast","Slow")) -> Fast | R20: =_xlfn.XLOOKUP(B20,CustomerMaster!$A$2:$A$287,CustomerMaster!$B$2:$B$287) -> Customer_199 | S20: =_xlfn.XLOOKUP(C20,ProductMaster!$A$2:$A$51,ProductMaster!$B$2:$B$51) -> Product_15 | T20: =_xlfn.XLOOKUP(G20,RegionMaster!$A$2:$A$5,RegionMaster!$B$2:$B$5) -> A
A21: ORD10019 | B21: CUST1156 | C21: PROD141 | D21: 45712 | E21: 45715 | G21: North | H21: Home | I21: Credit Card | J21: Cancelled | K21: 1597.9 | L21: =TEXT(D21,"MMMM") -> February | M21: =IF(NOT(ISBLANK(E21)),TEXT(E21,"MMMM"),"Cancelled") -> February | N21: =IF(F21="","Delivered","Cancelled") -> Delivered | O21: =IF(E21="","Order Cancelled",_xlfn.DAYS(E21,D21)) -> 3 | P21: =IF(F21="","Completed","Cancelled") -> Completed | Q21: =IF(O21="Order Cancelled","Cancelled",IF(O21<=2,"Fast","Slow")) -> Slow | R21: =_xlfn.XLOOKUP(B21,CustomerMaster!$A$2:$A$287,CustomerMaster!$B$2:$B$287) -> Customer_95 | S21: =_xlfn.XLOOKUP(C21,ProductMaster!$A$2:$A$51,ProductMaster!$B$2:$B$51) -> Product_29 | T21: =_xlfn.XLOOKUP(G21,RegionMaster!$A$2:$A$5,RegionMaster!$B$2:$B$5) -> A
A22: ORD10020 | B22: CUST1078 | C22: PROD105 | D22: 45761 | F22: 45762 | G22: East | H22: Home | I22: Credit Card | J22: Cancelled | K22: 3136.89 | L22: =TEXT(D22,"MMMM") -> April | M22: =IF(NOT(ISBLANK(E22)),TEXT(E22,"MMMM"),"Cancelled") -> Cancelled | N22: =IF(F22="","Delivered","Cancelled") -> Cancelled | O22: =IF(E22="","Order Cancelled",_xlfn.DAYS(E22,D22)) -> Order Cancelled | P22: =IF(F22="","Completed","Cancelled") -> Cancelled | Q22: =IF(O22="Order Cancelled","Cancelled",IF(O22<=2,"Fast","Slow")) -> Cancelled | R22: =_xlfn.XLOOKUP(B22,CustomerMaster!$A$2:$A$287,CustomerMaster!$B$2:$B$287) -> Customer_283 | S22: =_xlfn.XLOOKUP(C22,ProductMaster!$A$2:$A$51,ProductMaster!$B$2:$B$51) -> Product_11 | T22: =_xlfn.XLOOKUP(G22,RegionMaster!$A$2:$A$5,RegionMaster!$B$2:$B$5) -> C
A23: ORD10021 | B23: CUST1003 | C23: PROD114 | D23: 45658 | F23: 45660 | G23: West | H23: Home | I23: Net Banking | J23: Cancelled | K23: 869.57 | L23: =TEXT(D23,"MMMM") -> January | M23: =IF(NOT(ISBLANK(E23)),TEXT(E23,"MMMM"),"Cancelled") -> Cancelled | N23: =IF(F23="","Delivered","Cancelled") -> Cancelled | O23: =IF(E23="","Order Cancelled",_xlfn.DAYS(E23,D23)) -> Order Cancelled | P23: =IF(F23="","Completed","Cancelled") -> Cancelled | Q23: =IF(O23="Order Cancelled","Cancelled",IF(O23<=2,"Fast","Slow")) -> Cancelled | R23: =_xlfn.XLOOKUP(B23,CustomerMaster!$A$2:$A$287,CustomerMaster!$B$2:$B$287) -> Customer_232 | S23: =_xlfn.XLOOKUP(C23,ProductMaster!$A$2:$A$51,ProductMaster!$B$2:$B$51) -> Product_12 | T23: =_xlfn.XLOOKUP(G23,RegionMaster!$A$2:$A$5,RegionMaster!$B$2:$B$5) -> D
A24: ORD10022 | B24: CUST1235 | C24: PROD103 | D24: 45702 | F24: 45703 | G24: North | H24: Fashion | I24: Net Banking | J24: Cancelled | K24: 1602.29 | L24: =TEXT(D24,"MMMM") -> February | M24: =IF(NOT(ISBLANK(E24)),TEXT(E24,"MMMM"),"Cancelled") -> Cancelled | N24: =IF(F24="","Delivered","Cancelled") -> Cancelled | O24: =IF(E24="","Order Cancelled",_xlfn.DAYS(E24,D24)) -> Order Cancelled | P24: =IF(F24="","Completed","Cancelled") -> Cancelled | Q24: =IF(O24="Order Cancelled","Cancelled",IF(O24<=2,"Fast","Slow")) -> Cancelled | R24: =_xlfn.XLOOKUP(B24,CustomerMaster!$A$2:$A$287,CustomerMaster!$B$2:$B$287) -> Customer_267 | S24: =_xlfn.XLOOKUP(C24,ProductMaster!$A$2:$A$51,ProductMaster!$B$2:$B$51) -> Product_25 | T24: =_xlfn.XLOOKUP(G24,RegionMaster!$A$2:$A$5,RegionMaster!$B$2:$B$5) -> A
A25: ORD10023 | B25: CUST1229 | C25: PROD121 | D25: 45727 | E25: 45732 | G25: North | H25: Grocery | I25: Credit Card | J25: Returned | K25: 1958.54 | L25: =TEXT(D25,"MMMM") -> March | M25: =IF(NOT(ISBLANK(E25)),TEXT(E25,"MMMM"),"Cancelled") -> March | N25: =IF(F25="","Delivered","Cancelled") -> Delivered | O25: =IF(E25="","Order Cancelled",_xlfn.DAYS(E25,D25)) -> 5 | P25: =IF(F25="","Completed","Cancelled") -> Completed | Q25: =IF(O25="Order Cancelled","Cancelled",IF(O25<=2,"Fast","Slow")) -> Slow | R25: =_xlfn.XLOOKUP(B25,CustomerMaster!$A$2:$A$287,CustomerMaster!$B$2:$B$287) -> Customer_278 | S25: =_xlfn.XLOOKUP(C25,ProductMaster!$A$2:$A$51,ProductMaster!$B$2:$B$51) -> Product_14 | T25: =_xlfn.XLOOKUP(G25,RegionMaster!$A$2:$A$5,RegionMaster!$B$2:$B$5) -> A
A26: ORD10024 | B26: CUST1220 | C26: PROD138 | D26: 45692 | F26: 45692 | G26: East | H26: Electronics | I26: Credit Card | J26: Returned | K26: 2389.14 | L26: =TEXT(D26,"MMMM") -> February | M26: =IF(NOT(ISBLANK(E26)),TEXT(E26,"MMMM"),"Cancelled") -> Cancelled | N26: =IF(F26="","Delivered","Cancelled") -> Cancelled | O26: =IF(E26="","Order Cancelled",_xlfn.DAYS(E26,D26)) -> Order Cancelled | P26: =IF(F26="","Completed","Cancelled") -> Cancelled | Q26: =IF(O26="Order Cancelled","Cancelled",IF(O26<=2,"Fast","Slow")) -> Cancelled | R26: =_xlfn.XLOOKUP(B26,CustomerMaster!$A$2:$A$287,CustomerMaster!$B$2:$B$287) -> Customer_195 | S26: =_xlfn.XLOOKUP(C26,ProductMaster!$A$2:$A$51,ProductMaster!$B$2:$B$51) -> Product_38 | T26: =_xlfn.XLOOKUP(G26,RegionMaster!$A$2:$A$5,RegionMaster!$B$2:$B$5) -> C
A27: ORD10025 | B27: CUST1198 | C27: PROD143 | D27: 45777 | E27: 45780 | G27: North | H27: Electronics | I27: Net Banking | J27: Returned | K27: 3968.84 | L27: =TEXT(D27,"MMMM") -> April | M27: =IF(NOT(ISBLANK(E27)),TEXT(E27,"MMMM"),"Cancelled") -> May | N27: =IF(F27="","Delivered","Cancelled") -> Delivered | O27: =IF(E27="","Order Cancelled",_xlfn.DAYS(E27,D27)) -> 3 | P27: =IF(F27="","Completed","Cancelled") -> Completed | Q27: =IF(O27="Order Cancelled","Cancelled",IF(O27<=2,"Fast","Slow")) -> Slow | R27: =_xlfn.XLOOKUP(B27,CustomerMaster!$A$2:$A$287,CustomerMaster!$B$2:$B$287) -> Customer_107 | S27: =_xlfn.XLOOKUP(C27,ProductMaster!$A$2:$A$51,ProductMaster!$B$2:$B$51) -> Product_31 | T27: =_xlfn.XLOOKUP(G27,RegionMaster!$A$2:$A$5,RegionMaster!$B$2:$B$5) -> A
A28: ORD10026 | B28: CUST1152 | C28: PROD150 | D28: 45698 | E28: 45700 | G28: West | H28: Beauty | I28: COD | J28: Returned | K28: 1158.43 | L28: =TEXT(D28,"MMMM") -> February | M28: =IF(NOT(ISBLANK(E28)),TEXT(E28,"MMMM"),"Cancelled") -> February | N28: =IF(F28="","Delivered","Cancelled") -> Delivered | O28: =IF(E28="","Order Cancelled",_xlfn.DAYS(E28,D28)) -> 2 | P28: =IF(F28="","Completed","Cancelled") -> Completed | Q28: =IF(O28="Order Cancelled","Cancelled",IF(O28<=2,"Fast","Slow")) -> Fast | R28: =_xlfn.XLOOKUP(B28,CustomerMaster!$A$2:$A$287,CustomerMaster!$B$2:$B$287) -> Customer_42 | S28: =_xlfn.XLOOKUP(C28,ProductMaster!$A$2:$A$51,ProductMaster!$B$2:$B$51) -> Product_0 | T28: =_xlfn.XLOOKUP(G28,RegionMaster!$A$2:$A$5,RegionMaster!$B$2:$B$5) -> D
A29: ORD10027 | B29: CUST1106 | C29: PROD104 | D29: 45675 | E29: 45679 | G29: North | H29: Grocery | I29: Credit Card | J29: Returned | K29: 2668.33 | L29: =TEXT(D29,"MMMM") -> January | M29: =IF(NOT(ISBLANK(E29)),TEXT(E29,"MMMM"),"Cancelled") -> January | N29: =IF(F29="","Delivered","Cancelled") -> Delivered | O29: =IF(E29="","Order Cancelled",_xlfn.DAYS(E29,D29)) -> 4 | P29: =IF(F29="","Completed","Cancelled") -> Completed | Q29: =IF(O29="Order Cancelled","Cancelled",IF(O29<=2,"Fast","Slow")) -> Slow | R29: =_xlfn.XLOOKUP(B29,CustomerMaster!$A$2:$A$287,CustomerMaster!$B$2:$B$287) -> Customer_58 | S29: =_xlfn.XLOOKUP(C29,ProductMaster!$A$2:$A$51,ProductMaster!$B$2:$B$51) -> Product_3 | T29: =_xlfn.XLOOKUP(G29,RegionMaster!$A$2:$A$5,RegionMaster!$B$2:$B$5) -> A
A30: ORD10028 | B30: CUST1063 | C30: PROD120 | D30: 45729 | F30: 45731 | G30: South | H30: Fashion | I30: Credit Card | J30: Cancelled | K30: 3043.59 | L30: =TEXT(D30,"MMMM") -> March | M30: =IF(NOT(ISBLANK(E30)),TEXT(E30,"MMMM"),"Cancelled") -> Cancelled | N30: =IF(F30="","Delivered","Cancelled") -> Cancelled | O30: =IF(E30="","Order Cancelled",_xlfn.DAYS(E30,D30)) -> Order Cancelled | P30: =IF(F30="","Completed","Cancelled") -> Cancelled | Q30: =IF(O30="Order Cancelled","Cancelled",IF(O30<=2,"Fast","Slow")) -> Cancelled | R30: =_xlfn.XLOOKUP(B30,CustomerMaster!$A$2:$A$287,CustomerMaster!$B$2:$B$287) -> Customer_81 | S30: =_xlfn.XLOOKUP(C30,ProductMaster!$A$2:$A$51,ProductMaster!$B$2:$B$51) -> Product_8 | T30: =_xlfn.XLOOKUP(G30,RegionMaster!$A$2:$A$5,RegionMaster!$B$2:$B$5) -> B
A31: ORD10029 | B31: CUST1249 | C31: PROD142 | D31: 45773 | E31: 45777 | G31: East | H31: Grocery | I31: COD | J31: Delivered | K31: 422.96 | L31: =TEXT(D31,"MMMM") -> April | M31: =IF(NOT(ISBLANK(E31)),TEXT(E31,"MMMM"),"Cancelled") -> April | N31: =IF(F31="","Delivered","Cancelled") -> Delivered | O31: =IF(E31="","Order Cancelled",_xlfn.DAYS(E31,D31)) -> 4 | P31: =IF(F31="","Completed","Cancelled") -> Completed | Q31: =IF(O31="Order Cancelled","Cancelled",IF(O31<=2,"Fast","Slow")) -> Slow | R31: =_xlfn.XLOOKUP(B31,CustomerMaster!$A$2:$A$287,CustomerMaster!$B$2:$B$287) -> Customer_271 | S31: =_xlfn.XLOOKUP(C31,ProductMaster!$A$2:$A$51,ProductMaster!$B$2:$B$51) -> Product_45 | T31: =_xlfn.XLOOKUP(G31,RegionMaster!$A$2:$A$5,RegionMaster!$B$2:$B$5) -> C
A32: ORD10030 | B32: CUST1278 | C32: PROD125 | D32: 45696 | F32: 45696 | G32: West | H32: Electronics | I32: Net Banking | J32: Returned | K32: 3116.22 | L32: =TEXT(D32,"MMMM") -> February | M32: =IF(NOT(ISBLANK(E32)),TEXT(E32,"MMMM"),"Cancelled") -> Cancelled | N32: =IF(F32="","Delivered","Cancelled") -> Cancelled | O32: =IF(E32="","Order Cancelled",_xlfn.DAYS(E32,D32)) -> Order Cancelled | P32: =IF(F32="","Completed","Cancelled") -> Cancelled | Q32: =IF(O32="Order Cancelled","Cancelled",IF(O32<=2,"Fast","Slow")) -> Cancelled | R32: =_xlfn.XLOOKUP(B32,CustomerMaster!$A$2:$A$287,CustomerMaster!$B$2:$B$287) -> Customer_196 | S32: =_xlfn.XLOOKUP(C32,ProductMaster!$A$2:$A$51,ProductMaster!$B$2:$B$51) -> Product_32 | T32: =_xlfn.XLOOKUP(G32,RegionMaster!$A$2:$A$5,RegionMaster!$B$2:$B$5) -> D
A33: ORD10031 | B33: CUST1298 | C33: PROD125 | D33: 45736 | E33: 45741 | G33: West | H33: Grocery | I33: Debit Card | J33: Delivered | K33: 1018.52 | L33: =TEXT(D33,"MMMM") -> March | M33: =IF(NOT(ISBLANK(E33)),TEXT(E33,"MMMM"),"Cancelled") -> March | N33: =IF(F33="","Delivered","Cancelled") -> Delivered | O33: =IF(E33="","Order Cancelled",_xlfn.DAYS(E33,D33)) -> 5 | P33: =IF(F33="","Completed","Cancelled") -> Completed | Q33: =IF(O33="Order Cancelled","Cancelled",IF(O33<=2,"Fast","Slow")) -> Slow | R33: =_xlfn.XLOOKUP(B33,CustomerMaster!$A$2:$A$287,CustomerMaster!$B$2:$B$287) -> Customer_178 | S33: =_xlfn.XLOOKUP(C33,ProductMaster!$A$2:$A$51,ProductMaster!$B$2:$B$51) -> Product_32 | T33: =_xlfn.XLOOKUP(G33,RegionMaster!$A$2:$A$5,RegionMaster!$B$2:$B$5) -> D
A34: ORD10032 | B34: CUST1292 | C34: PROD145 | D34: 45710 | E34: 45715 | G34: North | H34: Electronics | I34: COD | J34: Delivered | K34: 512.25 | L34: =TEXT(D34,"MMMM") -> February | M34: =IF(NOT(ISBLANK(E34)),TEXT(E34,"MMMM"),"Cancelled") -> February | N34: =IF(F34="","Delivered","Cancelled") -> Delivered | O34: =IF(E34="","Order Cancelled",_xlfn.DAYS(E34,D34)) -> 5 | P34: =IF(F34="","Completed","Cancelled") -> Completed | Q34: =IF(O34="Order Cancelled","Cancelled",IF(O34<=2,"Fast","Slow")) -> Slow | R34: =_xlfn.XLOOKUP(B34,CustomerMaster!$A$2:$A$287,CustomerMaster!$B$2:$B$287) -> Customer_1 | S34: =_xlfn.XLOOKUP(C34,ProductMaster!$A$2:$A$51,ProductMaster!$B$2:$B$51) -> Product_36 | T34: =_xlfn.XLOOKUP(G34,RegionMaster!$A$2:$A$5,RegionMaster!$B$2:$B$5) -> A
A35: ORD10033 | B35: CUST1126 | C35: PROD117 | D35: 45766 | F35: 45767 | G35: North | H35: Grocery | I35: Debit Card | J35: Cancelled | K35: 4754.65 | L35: =TEXT(D35,"MMMM") -> April | M35: =IF(NOT(ISBLANK(E35)),TEXT(E35,"MMMM"),"Cancelled") -> Cancelled | N35: =IF(F35="","Delivered","Cancelled") -> Cancelled | O35: =IF(E35="","Order Cancelled",_xlfn.DAYS(E35,D35)) -> Order Cancelled | P35: =IF(F35="","Completed","Cancelled") -> Cancelled | Q35: =IF(O35="Order Cancelled","Cancelled",IF(O35<=2,"Fast","Slow")) -> Cancelled | R35: =_xlfn.XLOOKUP(B35,CustomerMaster!$A$2:$A$287,CustomerMaster!$B$2:$B$287) -> Customer_215 | S35: =_xlfn.XLOOKUP(C35,ProductMaster!$A$2:$A$51,ProductMaster!$B$2:$B$51) -> Product_18 | T35: =_xlfn.XLOOKUP(G35,RegionMaster!$A$2:$A$5,RegionMaster!$B$2:$B$5) -> A
A36: ORD10034 | B36: CUST1184 | C36: PROD117 | D36: 45732 | E36: 45735 | G36: North | H36: Beauty | I36: Credit Card | J36: Cancelled | K36: 4835.03 | L36: =TEXT(D36,"MMMM") -> March | M36: =IF(NOT(ISBLANK(E36)),TEXT(E36,"MMMM"),"Cancelled") -> March | N36: =IF(F36="","Delivered","Cancelled") -> Delivered | O36: =IF(E36="","Order Cancelled",_xlfn.DAYS(E36,D36)) -> 3 | P36: =IF(F36="","Completed","Cancelled") -> Completed | Q36: =IF(O36="Order Cancelled","Cancelled",IF(O36<=2,"Fast","Slow")) -> Slow | R36: =_xlfn.XLOOKUP(B36,CustomerMaster!$A$2:$A$287,CustomerMaster!$B$2:$B$287) -> Customer_50 | S36: =_xlfn.XLOOKUP(C36,ProductMaster!$A$2:$A$51,ProductMaster!$B$2:$B$51) -> Product_18 | T36: =_xlfn.XLOOKUP(G36,RegionMaster!$A$2:$A$5,RegionMaster!$B$2:$B$5) -> A
A37: ORD10035 | B37: CUST1051 | C37: PROD139 | D37: 45702 | E37: 45703 | G37: South | H37: Grocery | I37: Net Banking | J37: Delivered | K37: 4080.31 | L37: =TEXT(D37,"MMMM") -> February | M37: =IF(NOT(ISBLANK(E37)),TEXT(E37,"MMMM"),"Cancelled") -> February | N37: =IF(F37="","Delivered","Cancelled") -> Delivered | O37: =IF(E37="","Order Cancelled",_xlfn.DAYS(E37,D37)) -> 1 | P37: =IF(F37="","Completed","Cancelled") -> Completed | Q37: =IF(O37="Order Cancelled","Cancelled",IF(O37<=2,"Fast","Slow")) -> Fast | R37: =_xlfn.XLOOKUP(B37,CustomerMaster!$A$2:$A$287,CustomerMaster!$B$2:$B$287) -> Customer_52 | S37: =_xlfn.XLOOKUP(C37,ProductMaster!$A$2:$A$51,ProductMaster!$B$2:$B$51) -> Product_15 | T37: =_xlfn.XLOOKUP(G37,RegionMaster!$A$2:$A$5,RegionMaster!$B$2:$B$5) -> B
A38: ORD10036 | B38: CUST1125 | C38: PROD139 | D38: 45763 | E38: 45769 | G38: North | H38: Grocery | I38: Debit Card | J38: Returned | K38: 1662.15 | L38: =TEXT(D38,"MMMM") -> April | M38: =IF(NOT(ISBLANK(E38)),TEXT(E38,"MMMM"),"Cancelled") -> April | N38: =IF(F38="","Delivered","Cancelled") -> Delivered | O38: =IF(E38="","Order Cancelled",_xlfn.DAYS(E38,D38)) -> 6 | P38: =IF(F38="","Completed","Cancelled") -> Completed | Q38: =IF(O38="Order Cancelled","Cancelled",IF(O38<=2,"Fast","Slow")) -> Slow | R38: =_xlfn.XLOOKUP(B38,CustomerMaster!$A$2:$A$287,CustomerMaster!$B$2:$B$287) -> Customer_281 | S38: =_xlfn.XLOOKUP(C38,ProductMaster!$A$2:$A$51,ProductMaster!$B$2:$B$51) -> Product_15 | T38: =_xlfn.XLOOKUP(G38,RegionMaster!$A$2:$A$5,RegionMaster!$B$2:$B$5) -> A
A39: ORD10037 | B39: CUST1098 | C39: PROD147 | D39: 45699 | F39: 45701 | G39: North | H39: Electronics | I39: Credit Card | J39: Cancelled | K39: 668.83 | L39: =TEXT(D39,"MMMM") -> February | M39: =IF(NOT(ISBLANK(E39)),TEXT(E39,"MMMM"),"Cancelled") -> Cancelled | N39: =IF(F39="","Delivered","Cancelled") -> Cancelled | O39: =IF(E39="","Order Cancelled",_xlfn.DAYS(E39,D39)) -> Order Cancelled | P39: =IF(F39="","Completed","Cancelled") -> Cancelled | Q39: =IF(O39="Order Cancelled","Cancelled",IF(O39<=2,"Fast","Slow")) -> Cancelled | R39: =_xlfn.XLOOKUP(B39,CustomerMaster!$A$2:$A$287,CustomerMaster!$B$2:$B$287) -> Customer_66 | S39: =_xlfn.XLOOKUP(C39,ProductMaster!$A$2:$A$51,ProductMaster!$B$2:$B$51) -> Product_27 | T39: =_xlfn.XLOOKUP(G39,RegionMaster!$A$2:$A$5,RegionMaster!$B$2:$B$5) -> A
A40: ORD10038 | B40: CUST1172 | C40: PROD107 | D40: 45681 | E40: 45684 | G40: East | H40: Home | I40: Net Banking | J40: Cancelled | K40: 3484.32 | L40: =TEXT(D40,"MMMM") -> January | M40: =IF(NOT(ISBLANK(E40)),TEXT(E40,"MMMM"),"Cancelled") -> January | N40: =IF(F40="","Delivered","Cancelled") -> Delivered | O40: =IF(E40="","Order Cancelled",_xlfn.DAYS(E40,D40)) -> 3 | P40: =IF(F40="","Completed","Cancelled") -> Completed | Q40: =IF(O40="Order Cancelled","Cancelled",IF(O40<=2,"Fast","Slow")) -> Slow | R40: =_xlfn.XLOOKUP(B40,CustomerMaster!$A$2:$A$287,CustomerMaster!$B$2:$B$287) -> Customer_268 | S40: =_xlfn.XLOOKUP(C40,ProductMaster!$A$2:$A$51,ProductMaster!$B$2:$B$51) -> Product_43 | T40: =_xlfn.XLOOKUP(G40,RegionMaster!$A$2:$A$5,RegionMaster!$B$2:$B$5) -> C
...

Sheet pivot
B1: ● Total Sales by Region & Category
B3: Order Flag | C3: Completed
P4: Order Flag | Q4: Completed
B5: Sum of SalesAmount | C5: Column Labels
B6: Row Labels | C6: Beauty | D6: Electronics | E6: Fashion | F6: Grocery | G6: Home | H6: Grand Total | M6: KPIs | P6: Sum of SalesAmount
B7: East | C7: 64394.79 | D7: 98799.05 | E7: 89735.06 | F7: 81471.28 | G7: 102436.89 | H7: 436837.07 | L7: Total Revenue | M7: =GETPIVOTDATA("SalesAmount",$P$6) -> 1747718.2 | P7: 1747718.2
B8: North | C8: 75766.3 | D8: 91599.63 | E8: 96200.3 | F8: 74627.56 | G8: 112197.3 | H8: 450391.09 | L8: Total order | M8: =GETPIVOTDATA("OrderID",$P$9) -> 1000
B9: South | C9: 62105.82 | D9: 101312.44 | E9: 97828.87 | F9: 93661.09 | G9: 112017.04 | H9: 466925.26 | L9: Total customer | M9: =GETPIVOTDATA("CustomerID",$P$12) -> 1000 | P9: Count of OrderID
B10: West | C10: 72325.82 | D10: 81786.52 | E10: 84219.78 | F10: 81966.89 | G10: 73265.82 | H10: 393564.83 | L10: Cancellation rate | M10: =GETPIVOTDATA("Delivery Category",$P$18,"Delivery Category","Cancelled") -> 0.32 | P10: 1000
B11: Grand Total | C11: 274592.73 | D11: 373497.64 | E11: 367984.01 | F11: 331726.82 | G11: 399917.05 | H11: 1747718.2 | L11: Fast delivert % | M11: =GETPIVOTDATA("Order performance",$P$25,"Order performance","Fast") -> 0.28970588
P12: Count of CustomerID
H13: ● Sales by Payment Method | P13: 1000
H15: Order Flag | I15: Completed
B16: ● Count of Orders by Delivery Status
H17: Row Labels | I17: Sum of SalesAmount
B18: Row Labels | C18: Count of OrderID | H18: Net Banking | I18: 379377.58 | P18: Row Labels | Q18: Count of Delivery Category
B19: Delivered | C19: 680 | H19: COD | I19: 365034.34 | P19: Cancelled | Q19: 0.32
B20: Cancelled | C20: 320 | H20: Debit Card | I20: 342915.39 | P20: Delivered | Q20: 0.68
B21: Grand Total | C21: 1000 | H21: Credit Card | I21: 332299.06 | P21: Grand Total | Q21: 1
H22: UPI | I22: 328091.88
H23: Grand Total | I23: 1747718.2 | P23: Order Flag | Q23: Completed
P25: Row Labels | Q25: Count of Order performance
H26: Order Flag | I26: Cancelled | P26: Fast | Q26: 0.28970588
P27: Slow | Q27: 0.71029412
B28: ● Avg Delivery Time by Region | H28: Row Labels | I28: Count of Order Flag | P28: Grand Total | Q28: 1
H29: UPI | I29: 0.234375
B30: Row Labels | C30: Average of Delivery Days | H30: Debit Card | I30: 0.209375
B31: East | C31: 3.65 | H31: Credit Card | I31: 0.20625
B32: North | C32: 3.6298343 | H32: Net Banking | I32: 0.1875
B33: South | C33: 3.4468085 | H33: COD | I33: 0.1625
B34: West | C34: 3.3576159 | H34: Grand Total | I34: 1
B35: Grand Total | C35: 3.5235294
C37: Order Flag | D37: Completed
C39: Row Labels | D39: Sum of SalesAmount
C40: West | D40: 393564.83
C41: East | D41: 436837.07
C42: North | D42: 450391.09
C43: South | D43: 466925.26
C44: Grand Total | D44: 1747718.2
C49: Count of Order performance | D49: Column Labels
...

Sheet Dashboard
